Workbook

Sheet Overview
B2: SaaS Market 2026 — Pricing & Positioning Analysis
B3: Source: ComparEdge (Kaggle) — 331 SaaS products across 28 categories, snapshot dated 2026-04-27
B5: Total Products | C5: Categories | D5: Median Entry Price | E5: % With Free Tier
B6: =COUNTA(Products!B2:B332) | C6: =COUNTA('Category Summary'!A2:A29) | D6: =TEXT(MEDIAN(Products!S2:S332),"$0.00/mo") | E6: =ROUND(COUNTIF(Products!J2:J332,TRUE)/COUNTA(Products!B2:B332)*100,1)&"%"
B9: How to read this workbook
B10: • Products — one row per SaaS product (cleaned from a SQLite relational export). 'entry_price_comparable' is a helper column used by every downstream formula.
B11: • Pricing Plans — one row per pricing tier per product (1,013 total).
B12: • Category Summary — category-level stats computed live with AVERAGEIF/COUNTIFS formulas against the Products sheet, not pasted-in numbers.
B13: • Billing Models — mix of flat / per-seat / usage-based / per-project billing across all pricing plans.
B14: • Dashboard — charts built from the Category Summary and Billing Models tables.
B17: Known data quality issues (see sql/02_data_quality_checks.sql for detection queries)
B18: • 'ai-tools' was a phantom umbrella category (104 products claimed, 0 actually tagged) — removed; the real AI products live in the ai-* subcategories + LLM.
B19: • 'DEX' pricing_plans.price_monthly stores swap-fee percentages, not USD/month subscription prices — excluded from all price comparisons (price_comparable = FALSE).
B20: • products.review_count is 0 for every row (unpopulated in the source data) — not used anywhere as a reliability signal.
B21: • ~11 products have no overall_rating and ~89 have at least one custom/'Contact Sales' plan — both kept as-is (blank/N/A) rather than guessed at.
B22: • A few category names were auto-titlecased acronyms ('Crm', 'Dex', 'Vpn') — corrected to CRM, DEX, VPN, DeFi Tools.

Sheet Dashboard
B2: SaaS Market 2026 — Dashboard

Sheet Products
A1: product_id | B1: name | C1: category_slug | D1: category_name | E1: overall_rating | F1: g2_rating | G1: capterra_rating | H1: founded_year | I1: hq_location | J1: has_free_tier | K1: has_free_trial | L1: has_custom_pricing | M1: price_comparable | N1: entry_price | O1: max_price_monthly | P1: plan_count | Q1: feature_count | R1: website_url | S1: entry_price_comparable
A2: 67 | B2: 10Web | C2: website-builders | D2: Website Builders | E2: 4.55 | F2: 4.6 | G2: 4.5 | H2: 2017 | I2: Yerevan, Armenia / Wilmington, DE | J2: FALSE | K2: FALSE | L2: FALSE | M2: TRUE | N2: 10 | O2: 60 | P2: 3 | Q2: 9 | R2: https://10web.io | S2: =IF(M2,N2,"")
A3: 157 | B3: 1Password | C3: password-managers | D3: Password Managers | E3: 4.75 | F3: 4.8 | G3: 4.7 | H3: 2006 | J3: FALSE | K3: FALSE | L3: FALSE | M3: TRUE | N3: 2.99 | O3: 7.99 | P3: 3 | Q3: 14 | R3: https://1password.com | S3: =IF(M3,N3,"")
A4: 292 | B4: 1inch | C4: defi-tools | D4: DeFi Tools | E4: 4.3 | F4: 4.3 | H4: 2019 | I4: Cayman Islands | J4: TRUE | K4: FALSE | L4: FALSE | M4: TRUE | O4: 0 | P4: 1 | Q4: 10 | R4: https://1inch.io | S4: =IF(M4,N4,"")
A5: 265 | B5: 3Commas | C5: crypto-trading-bots | D5: Crypto Trading Bots | E5: 4.25 | F5: 4.3 | G5: 4.2 | H5: 2017 | I5: Tallinn, Estonia | J5: TRUE | K5: FALSE | L5: FALSE | M5: TRUE | N5: 15 | O5: 60 | P5: 4 | Q5: 12 | R5: https://3commas.io | S5: =IF(M5,N5,"")
A6: 87 | B6: A2 Hosting | C6: cloud-hosting | D6: Cloud Hosting | E6: 4.35 | F6: 4.3 | G6: 4.4 | H6: 2003 | I6: Ann Arbor, MI | J6: FALSE | K6: FALSE | L6: FALSE | M6: TRUE | N6: 2.99 | O6: 14.99 | P6: 4 | Q6: 9 | R6: https://www.a2hosting.com | S6: =IF(M6,N6,"")
A7: 196 | B7: AI21 Studio | C7: ai-writing | D7: AI Writing | E7: 4.35 | F7: 4.4 | G7: 4.3 | H7: 2017 | J7: TRUE | K7: FALSE | L7: TRUE | M7: TRUE | N7: 39 | O7: 39 | P7: 3 | Q7: 6 | R7: https://studio.ai21.com | S7: =IF(M7,N7,"")
A8: 43 | B8: AWeber | C8: email-marketing | D8: Email Marketing | E8: 4.3 | F8: 4.2 | G8: 4.4 | H8: 1998 | I8: Chalfont, PA | J8: TRUE | K8: FALSE | L8: FALSE | M8: TRUE | N8: 14.99 | O8: 899 | P8: 4 | Q8: 12 | R8: https://www.aweber.com | S8: =IF(M8,N8,"")
A9: 286 | B9: Accointing (Blockpit) | C9: crypto-tax | D9: Crypto Tax | E9: 4.1 | F9: 4.1 | H9: 2017 | I9: Vienna, Austria | J9: TRUE | K9: FALSE | L9: FALSE | M9: TRUE | N9: 49 | O9: 199 | P9: 4 | Q9: 6 | R9: https://www.blockpit.io | S9: =IF(M9,N9,"")
A10: 39 | B10: ActiveCampaign | C10: email-marketing | D10: Email Marketing | E10: 4.55 | F10: 4.5 | G10: 4.6 | H10: 2003 | I10: Chicago, IL | J10: FALSE | K10: FALSE | L10: FALSE | M10: TRUE | N10: 15 | O10: 145 | P10: 4 | Q10: 17 | R10: https://www.activecampaign.com | S10: =IF(M10,N10,"")
A11: 170 | B11: Adobe Firefly | C11: ai-image | D11: AI Image Generators | E11: 4.45 | F11: 4.4 | G11: 4.5 | H11: 2023 | J11: TRUE | K11: FALSE | L11: FALSE | M11: TRUE | N11: 5 | O11: 5 | P11: 2 | Q11: 5 | R11: https://firefly.adobe.com | S11: =IF(M11,N11,"")
A12: 98 | B12: Adobe Illustrator | C12: design-tools | D12: Design Tools | E12: 4.65 | F12: 4.6 | G12: 4.7 | H12: 1987 | I12: San Jose, CA (Adobe) | J12: FALSE | K12: FALSE | L12: FALSE | M12: TRUE | N12: 22.99 | O12: 59.99 | P12: 2 | Q12: 6 | R12: https://www.adobe.com/products/illustrator.html | S12: =IF(M12,N12,"")
A13: 99 | B13: Adobe Photoshop | C13: design-tools | D13: Design Tools | E13: 4.7 | F13: 4.6 | G13: 4.8 | H13: 1990 | I13: San Jose, CA (Adobe) | J13: FALSE | K13: FALSE | L13: FALSE | M13: TRUE | N13: 9.99 | O13: 59.99 | P13: 3 | Q13: 8 | R13: https://www.adobe.com/products/photoshop.html | S13: =IF(M13,N13,"")
A14: 222 | B14: Adobe Podcast (Enhance) | C14: ai-voice | D14: AI Voice & Audio | E14: 4.6 | F14: 4.6 | G14: 4.6 | H14: 2022 | J14: TRUE | K14: FALSE | L14: FALSE | M14: TRUE | N14: 5 | O14: 5 | P14: 2 | Q14: 4 | R14: https://podcast.adobe.com | S14: =IF(M14,N14,"")
A15: 93 | B15: Adobe XD | C15: design-tools | D15: Design Tools | E15: 4.4 | F15: 4.3 | G15: 4.5 | H15: 2016 | I15: San Jose, CA (Adobe) | J15: FALSE | K15: FALSE | L15: FALSE | M15: TRUE | N15: 59.99 | O15: 59.99 | P15: 1 | Q15: 14 | R15: https://www.adobe.com/products/xd.html | S15: =IF(M15,N15,"")
A16: 97 | B16: Affinity Designer | C16: design-tools | D16: Design Tools | E16: 4.6 | F16: 4.5 | G16: 4.7 | H16: 2014 | I16: Nottingham, UK (Canva) | J16: FALSE | K16: FALSE | L16: FALSE | M16: TRUE | N16: 14.99 | O16: 169.99 | P16: 3 | Q16: 6 | R16: https://affinity.serif.com/en-us/designer/ | S16: =IF(M16,N16,"")
A17: 14 | B17: Airtable | C17: project-management | D17: Project Management | E17: 4.65 | F17: 4.6 | G17: 4.7 | H17: 2012 | I17: San Francisco, CA | J17: TRUE | K17: FALSE | L17: TRUE | M17: TRUE | N17: 20 | O17: 45 | P17: 4 | Q17: 13 | R17: https://airtable.com | S17: =IF(M17,N17,"")
A18: 118 | B18: Akaunting | C18: accounting | D18: Accounting | E18: 4.3 | F18: 4.2 | G18: 4.4 | H18: 2017 | I18: London, UK | J18: TRUE | K18: FALSE | L18: FALSE | M18: TRUE | N18: 15 | O18: 15 | P18: 2 | Q18: 13 | R18: https://akaunting.com | S18: =IF(M18,N18,"")
A19: 272 | B19: Altrady | C19: crypto-trading-bots | D19: Crypto Trading Bots | E19: 4.2 | F19: 4.2 | H19: 2018 | I19: Amsterdam, Netherlands | J19: TRUE | K19: FALSE | L19: FALSE | M19: TRUE | N19: 19 | O19: 55 | P19: 4 | Q19: 9 | R19: https://altrady.com | S19: =IF(M19,N19,"")
A20: 71 | B20: Amazon Web Services (AWS) | C20: cloud-hosting | D20: Cloud Hosting | E20: 4.55 | F20: 4.5 | G20: 4.6 | H20: 2006 | I20: Seattle, WA | J20: TRUE | K20: FALSE | L20: TRUE | M20: TRUE | O20: 0 | P20: 2 | Q20: 19 | R20: https://aws.amazon.com | S20: =IF(M20,N20,"")
A21: 212 | B21: Anthropic API (Claude) | C21: llm | D21: Large Language Models | E21: 4.65 | F21: 4.7 | G21: 4.6 | H21: 2021 | J21: FALSE | K21: FALSE | L21: TRUE | M21: TRUE | O21: 0 | P21: 2 | Q21: 9 | R21: https://anthropic.com/api | S21: =IF(M21,N21,"")
A22: 129 | B22: Around | C22: video-conferencing | D22: Video Conferencing | E22: 4.35 | F22: 4.4 | G22: 4.3 | H22: 2020 | I22: San Francisco, CA (Miro) | J22: TRUE | K22: FALSE | L22: FALSE | M22: TRUE | O22: 0 | P22: 1 | Q22: 4 | R22: https://www.around.co | S22: =IF(M22,N22,"")
A23: 3 | B23: Asana | C23: project-management | D23: Project Management | E23: 4.45 | F23: 4.4 | G23: 4.5 | H23: 2008 | I23: San Francisco, CA | J23: TRUE | K23: FALSE | L23: TRUE | M23: TRUE | N23: 10.99 | O23: 24.99 | P23: 4 | Q23: 15 | R23: https://asana.com | S23: =IF(M23,N23,"")
A24: 36 | B24: Attio | C24: crm | D24: CRM | E24: 4.75 | F24: 4.8 | G24: 4.7 | H24: 2019 | I24: London, UK | J24: TRUE | K24: FALSE | L24: TRUE | M24: TRUE | N24: 34 | O24: 69 | P24: 4 | Q24: 11 | R24: https://attio.com | S24: =IF(M24,N24,"")
A25: 250 | B25: AutoGPT | C25: ai-agents | D25: AI Agents | E25: 3.75 | F25: 3.8 | G25: 3.7 | H25: 2023 | J25: TRUE | K25: FALSE | L25: FALSE | M25: TRUE | O25: 0 | P25: 2 | Q25: 18 | R25: https://agpt.co | S25: =IF(M25,N25,"")
A26: 307 | B26: BONKbot | C26: crypto-telegram-bots | D26: Crypto Telegram Bots | E26: 4 | F26: 4 | H26: 2023 | I26: Unknown | J26: TRUE | K26: FALSE | L26: FALSE | M26: TRUE | O26: 0 | P26: 1 | Q26: 4 | R26: https://bonkbot.io | S26: =IF(M26,N26,"")
A27: 306 | B27: Banana Gun | C27: crypto-telegram-bots | D27: Crypto Telegram Bots | E27: 4.3 | F27: 4.3 | H27: 2023 | I27: Unknown | J27: TRUE | K27: FALSE | L27: FALSE | M27: TRUE | O27: 0 | P27: 1 | Q27: 9 | R27: https://bananagun.io | S27: =IF(M27,N27,"")
A28: 7 | B28: Basecamp | C28: project-management | D28: Project Management | E28: 4.2 | F28: 4.1 | G28: 4.3 | H28: 2004 | I28: Chicago, IL | J28: TRUE | K28: FALSE | L28: FALSE | M28: TRUE | N28: 15 | O28: 299 | P28: 3 | Q28: 9 | R28: https://basecamp.com | S28: =IF(M28,N28,"")
A29: 226 | B29: Beautiful.ai | C29: ai-productivity | D29: AI Productivity | E29: 4.45 | F29: 4.4 | G29: 4.5 | H29: 2016 | J29: FALSE | K29: FALSE | L29: TRUE | M29: TRUE | N29: 12 | O29: 40 | P29: 3 | Q29: 10 | R29: https://beautiful.ai | S29: =IF(M29,N29,"")
A30: 114 | B30: Bench | C30: accounting | D30: Accounting | E30: 4.45 | F30: 4.5 | G30: 4.4 | H30: 2012 | I30: Vancouver, Canada | J30: FALSE | K30: FALSE | L30: FALSE | M30: TRUE | N30: 189 | O30: 339 | P30: 2 | Q30: 7 | R30: https://bench.co | S30: =IF(M30,N30,"")
A31: 297 | B31: Binance | C31: crypto-exchanges | D31: Crypto Exchanges | E31: 4.35 | F31: 4.4 | G31: 4.3 | H31: 2017 | I31: Cayman Islands | J31: TRUE | K31: FALSE | L31: TRUE | M31: TRUE | O31: 0 | P31: 3 | Q31: 11 | R31: https://www.binance.com | S31: =IF(M31,N31,"")
A32: 304 | B32: Bitget | C32: crypto-exchanges | D32: Crypto Exchanges | E32: 4.1 | F32: 4.1 | H32: 2018 | I32: Seychelles | J32: TRUE | K32: FALSE | L32: TRUE | M32: TRUE | O32: 0 | P32: 3 | Q32: 7 | R32: https://www.bitget.com | S32: =IF(M32,N32,"")
A33: 268 | B33: Bitsgap | C33: crypto-trading-bots | D33: Crypto Trading Bots | E33: 4.2 | F33: 4.2 | H33: 2018 | I33: Tallinn, Estonia | J33: TRUE | K33: FALSE | L33: FALSE | M33: TRUE | N33: 23 | O33: 119 | P33: 4 | Q33: 8 | R33: https://bitsgap.com | S33: =IF(M33,N33,"")
A34: 158 | B34: Bitwarden | C34: password-managers | D34: Password Managers | E34: 4.75 | F34: 4.7 | G34: 4.8 | H34: 2016 | J34: TRUE | K34: FALSE | L34: FALSE | M34: TRUE | N34: 1 | O34: 4 | P34: 3 | Q34: 9 | R34: https://bitwarden.com | S34: =IF(M34,N34,"")
A35: 311 | B35: Bloom | C35: crypto-telegram-bots | D35: Crypto Telegram Bots | E35: 4.2 | F35: 4.2 | H35: 2023 | I35: Unknown | J35: TRUE | K35: FALSE | L35: FALSE | M35: TRUE | O35: 0 | P35: 1 | Q35: 14 | R35: https://bloombot.app | S35: =IF(M35,N35,"")
A36: 88 | B36: Bluehost | C36: cloud-hosting | D36: Cloud Hosting | E36: 4 | F36: 3.7 | G36: 4.3 | H36: 2003 | I36: Burlington, MA (Newfold Digital) | J36: FALSE | K36: FALSE | L36: FALSE | M36: TRUE | N36: 2.95 | O36: 9.95 | P36: 4 | Q36: 16 | R36: https://www.bluehost.com | S36: =IF(M36,N36,"")
A37: 206 | B37: Bolt.new | C37: ai-coding | D37: AI Coding | E37: 4.55 | F37: 4.6 | G37: 4.5 | H37: 2024 | J37: TRUE | K37: FALSE | L37: FALSE | M37: TRUE | N37: 25 | O37: 30 | P37: 3 | Q37: 8 | R37: https://bolt.new | S37: =IF(M37,N37,"")
A38: 116 | B38: Bonsai | C38: accounting | D38: Accounting | E38: 4.4 | F38: 4.3 | G38: 4.5 | H38: 2016 | I38: San Francisco, CA | J38: FALSE | K38: FALSE | L38: FALSE | M38: TRUE | N38: 9 | O38: 29 | P38: 3 | Q38: 10 | R38: https://www.hellobonsai.com | S38: =IF(M38,N38,"")
A39: 258 | B39: Botpress | C39: ai-assistants | D39: AI Assistants | E39: 4.55 | F39: 4.6 | G39: 4.5 | H39: 2016 | J39: TRUE | K39: FALSE | L39: FALSE | M39: TRUE | N39: 89 | O39: 89 | P39: 2 | Q39: 13 | R39: https://botpress.com | S39: =IF(M39,N39,"")
A40: 40 | B40: Brevo (Sendinblue) | C40: email-marketing | D40: Email Marketing | E40: 4.5 | F40: 4.5 | G40: 4.5 | H40: 2012 | I40: Paris, France | J40: FALSE | K40: FALSE | L40: TRUE | M40: TRUE | N40: 9 | O40: 49 | P40: 4 | Q40: 17 | R40: https://www.brevo.com | S40: =IF(M40,N40,"")
...

Sheet Pricing Plans
A1: id | B1: product_name | C1: plan_name | D1: price_monthly | E1: price_annual | F1: billing_model
A2: 1 | B2: Notion | C2: Free | D2: 0 | F2: per-seat
A3: 2 | B3: Notion | C3: Plus | D3: 12 | F3: per-seat
A4: 3 | B4: Notion | C4: Business | D4: 18 | F4: per-seat
A5: 4 | B5: Notion | C5: Enterprise | F5: per-seat
A6: 5 | B6: ClickUp | C6: Free | D6: 0 | F6: flat
A7: 6 | B7: ClickUp | C7: Unlimited | D7: 7 | F7: per-seat
A8: 7 | B8: ClickUp | C8: Business | D8: 12 | F8: per-seat
A9: 8 | B9: ClickUp | C9: Enterprise | F9: per-seat
A10: 9 | B10: Asana | C10: Personal | D10: 0 | F10: flat
A11: 10 | B11: Asana | C11: Starter | D11: 10.99 | F11: per-seat
A12: 11 | B12: Asana | C12: Advanced | D12: 24.99 | F12: per-seat
A13: 12 | B13: Asana | C13: Enterprise | F13: per-seat
A14: 13 | B14: monday.com | C14: Free | D14: 0 | F14: flat
A15: 14 | B15: monday.com | C15: Basic | D15: 9 | F15: per-seat
A16: 15 | B16: monday.com | C16: Standard | D16: 12 | F16: per-seat
A17: 16 | B17: monday.com | C17: Pro | D17: 19 | F17: per-seat
A18: 17 | B18: monday.com | C18: Enterprise | F18: per-seat
A19: 18 | B19: Trello | C19: Free | D19: 0 | F19: flat
A20: 19 | B20: Trello | C20: Standard | D20: 5 | F20: per-seat
A21: 20 | B21: Trello | C21: Premium | D21: 10 | F21: per-seat
A22: 21 | B22: Trello | C22: Enterprise | D22: 17.5 | F22: per-seat
A23: 22 | B23: Jira | C23: Free | D23: 0 | F23: flat
A24: 23 | B24: Jira | C24: Standard | D24: 7.91 | F24: per-seat
A25: 24 | B25: Jira | C25: Premium | D25: 14.54 | F25: per-seat
A26: 25 | B26: Jira | C26: Enterprise | F26: per-seat
A27: 26 | B27: Basecamp | C27: Free | D27: 0 | F27: flat
A28: 27 | B28: Basecamp | C28: Basecamp Plus | D28: 15 | F28: per-seat
A29: 28 | B29: Basecamp | C29: Basecamp Pro Unlimited | D29: 299 | F29: flat
A30: 29 | B30: Wrike | C30: Free | D30: 0 | F30: flat
A31: 30 | B31: Wrike | C31: Team | D31: 10 | F31: per-seat
A32: 31 | B32: Wrike | C32: Business | D32: 25 | F32: per-seat
A33: 32 | B33: Wrike | C33: Pinnacle | F33: per-seat
A34: 33 | B34: Teamwork | C34: Free | D34: 0 | F34: flat
A35: 34 | B35: Teamwork | C35: Deliver | D35: 13.99 | F35: per-seat
A36: 35 | B36: Teamwork | C36: Grow | D36: 25.99 | F36: per-seat
A37: 36 | B37: Teamwork | C37: Scale | D37: 69.99 | F37: per-seat
A38: 37 | B38: Linear | C38: Free | D38: 0 | F38: flat
A39: 38 | B39: Linear | C39: Basic | D39: 10 | F39: per-seat
A40: 39 | B40: Linear | C40: Business | D40: 16 | F40: per-seat
...

Sheet Category Summary
A1: category_name | B1: product_count | C1: avg_rating | D1: avg_entry_price | E1: free_tier_count | F1: free_tier_pct | G1: avg_feature_count
A2: AI Agents | B2: =COUNTIF(Products!D2:D332,A2) | C2: =ROUND(AVERAGEIF(Products!D2:D332,A2,Products!E2:E332),2) | D2: =IFERROR(ROUND(AVERAGEIF(Products!D2:D332,A2,Products!S2:S332),2),"N/A") | E2: =COUNTIFS(Products!D2:D332,A2,Products!J2:J332,TRUE) | F2: =ROUND(E2/B2*100,1) | G2: =ROUND(AVERAGEIF(Products!D2:D332,A2,Products!Q2:Q332),2)
A3: AI Assistants | B3: =COUNTIF(Products!D2:D332,A3) | C3: =ROUND(AVERAGEIF(Products!D2:D332,A3,Products!E2:E332),2) | D3: =IFERROR(ROUND(AVERAGEIF(Products!D2:D332,A3,Products!S2:S332),2),"N/A") | E3: =COUNTIFS(Products!D2:D332,A3,Products!J2:J332,TRUE) | F3: =ROUND(E3/B3*100,1) | G3: =ROUND(AVERAGEIF(Products!D2:D332,A3,Products!Q2:Q332),2)
A4: AI Coding | B4: =COUNTIF(Products!D2:D332,A4) | C4: =ROUND(AVERAGEIF(Products!D2:D332,A4,Products!E2:E332),2) | D4: =IFERROR(ROUND(AVERAGEIF(Products!D2:D332,A4,Products!S2:S332),2),"N/A") | E4: =COUNTIFS(Products!D2:D332,A4,Products!J2:J332,TRUE) | F4: =ROUND(E4/B4*100,1) | G4: =ROUND(AVERAGEIF(Products!D2:D332,A4,Products!Q2:Q332),2)
A5: AI Image Generators | B5: =COUNTIF(Products!D2:D332,A5) | C5: =ROUND(AVERAGEIF(Products!D2:D332,A5,Products!E2:E332),2) | D5: =IFERROR(ROUND(AVERAGEIF(Products!D2:D332,A5,Products!S2:S332),2),"N/A") | E5: =COUNTIFS(Products!D2:D332,A5,Products!J2:J332,TRUE) | F5: =ROUND(E5/B5*100,1) | G5: =ROUND(AVERAGEIF(Products!D2:D332,A5,Products!Q2:Q332),2)
A6: AI Productivity | B6: =COUNTIF(Products!D2:D332,A6) | C6: =ROUND(AVERAGEIF(Products!D2:D332,A6,Products!E2:E332),2) | D6: =IFERROR(ROUND(AVERAGEIF(Products!D2:D332,A6,Products!S2:S332),2),"N/A") | E6: =COUNTIFS(Products!D2:D332,A6,Products!J2:J332,TRUE) | F6: =ROUND(E6/B6*100,1) | G6: =ROUND(AVERAGEIF(Products!D2:D332,A6,Products!Q2:Q332),2)
A7: AI Video | B7: =COUNTIF(Products!D2:D332,A7) | C7: =ROUND(AVERAGEIF(Products!D2:D332,A7,Products!E2:E332),2) | D7: =IFERROR(ROUND(AVERAGEIF(Products!D2:D332,A7,Products!S2:S332),2),"N/A") | E7: =COUNTIFS(Products!D2:D332,A7,Products!J2:J332,TRUE) | F7: =ROUND(E7/B7*100,1) | G7: =ROUND(AVERAGEIF(Products!D2:D332,A7,Products!Q2:Q332),2)
A8: AI Voice & Audio | B8: =COUNTIF(Products!D2:D332,A8) | C8: =ROUND(AVERAGEIF(Products!D2:D332,A8,Products!E2:E332),2) | D8: =IFERROR(ROUND(AVERAGEIF(Products!D2:D332,A8,Products!S2:S332),2),"N/A") | E8: =COUNTIFS(Products!D2:D332,A8,Products!J2:J332,TRUE) | F8: =ROUND(E8/B8*100,1) | G8: =ROUND(AVERAGEIF(Products!D2:D332,A8,Products!Q2:Q332),2)
A9: AI Writing | B9: =COUNTIF(Products!D2:D332,A9) | C9: =ROUND(AVERAGEIF(Products!D2:D332,A9,Products!E2:E332),2) | D9: =IFERROR(ROUND(AVERAGEIF(Products!D2:D332,A9,Products!S2:S332),2),"N/A") | E9: =COUNTIFS(Products!D2:D332,A9,Products!J2:J332,TRUE) | F9: =ROUND(E9/B9*100,1) | G9: =ROUND(AVERAGEIF(Products!D2:D332,A9,Products!Q2:Q332),2)
A10: Accounting | B10: =COUNTIF(Products!D2:D332,A10) | C10: =ROUND(AVERAGEIF(Products!D2:D332,A10,Products!E2:E332),2) | D10: =IFERROR(ROUND(AVERAGEIF(Products!D2:D332,A10,Products!S2:S332),2),"N/A") | E10: =COUNTIFS(Products!D2:D332,A10,Products!J2:J332,TRUE) | F10: =ROUND(E10/B10*100,1) | G10: =ROUND(AVERAGEIF(Products!D2:D332,A10,Products!Q2:Q332),2)
A11: CRM | B11: =COUNTIF(Products!D2:D332,A11) | C11: =ROUND(AVERAGEIF(Products!D2:D332,A11,Products!E2:E332),2) | D11: =IFERROR(ROUND(AVERAGEIF(Products!D2:D332,A11,Products!S2:S332),2),"N/A") | E11: =COUNTIFS(Products!D2:D332,A11,Products!J2:J332,TRUE) | F11: =ROUND(E11/B11*100,1) | G11: =ROUND(AVERAGEIF(Products!D2:D332,A11,Products!Q2:Q332),2)
A12: Cloud Hosting | B12: =COUNTIF(Products!D2:D332,A12) | C12: =ROUND(AVERAGEIF(Products!D2:D332,A12,Products!E2:E332),2) | D12: =IFERROR(ROUND(AVERAGEIF(Products!D2:D332,A12,Products!S2:S332),2),"N/A") | E12: =COUNTIFS(Products!D2:D332,A12,Products!J2:J332,TRUE) | F12: =ROUND(E12/B12*100,1) | G12: =ROUND(AVERAGEIF(Products!D2:D332,A12,Products!Q2:Q332),2)
A13: Crypto Analytics | B13: =COUNTIF(Products!D2:D332,A13) | C13: =ROUND(AVERAGEIF(Products!D2:D332,A13,Products!E2:E332),2) | D13: =IFERROR(ROUND(AVERAGEIF(Products!D2:D332,A13,Products!S2:S332),2),"N/A") | E13: =COUNTIFS(Products!D2:D332,A13,Products!J2:J332,TRUE) | F13: =ROUND(E13/B13*100,1) | G13: =ROUND(AVERAGEIF(Products!D2:D332,A13,Products!Q2:Q332),2)
A14: Crypto Exchanges | B14: =COUNTIF(Products!D2:D332,A14) | C14: =ROUND(AVERAGEIF(Products!D2:D332,A14,Products!E2:E332),2) | D14: =IFERROR(ROUND(AVERAGEIF(Products!D2:D332,A14,Products!S2:S332),2),"N/A") | E14: =COUNTIFS(Products!D2:D332,A14,Products!J2:J332,TRUE) | F14: =ROUND(E14/B14*100,1) | G14: =ROUND(AVERAGEIF(Products!D2:D332,A14,Products!Q2:Q332),2)
A15: Crypto Portfolio Trackers | B15: =COUNTIF(Products!D2:D332,A15) | C15: =ROUND(AVERAGEIF(Products!D2:D332,A15,Products!E2:E332),2) | D15: =IFERROR(ROUND(AVERAGEIF(Products!D2:D332,A15,Products!S2:S332),2),"N/A") | E15: =COUNTIFS(Products!D2:D332,A15,Products!J2:J332,TRUE) | F15: =ROUND(E15/B15*100,1) | G15: =ROUND(AVERAGEIF(Products!D2:D332,A15,Products!Q2:Q332),2)
A16: Crypto Tax | B16: =COUNTIF(Products!D2:D332,A16) | C16: =ROUND(AVERAGEIF(Products!D2:D332,A16,Products!E2:E332),2) | D16: =IFERROR(ROUND(AVERAGEIF(Products!D2:D332,A16,Products!S2:S332),2),"N/A") | E16: =COUNTIFS(Products!D2:D332,A16,Products!J2:J332,TRUE) | F16: =ROUND(E16/B16*100,1) | G16: =ROUND(AVERAGEIF(Products!D2:D332,A16,Products!Q2:Q332),2)
A17: Crypto Telegram Bots | B17: =COUNTIF(Products!D2:D332,A17) | C17: =ROUND(AVERAGEIF(Products!D2:D332,A17,Products!E2:E332),2) | D17: =IFERROR(ROUND(AVERAGEIF(Products!D2:D332,A17,Products!S2:S332),2),"N/A") | E17: =COUNTIFS(Products!D2:D332,A17,Products!J2:J332,TRUE) | F17: =ROUND(E17/B17*100,1) | G17: =ROUND(AVERAGEIF(Products!D2:D332,A17,Products!Q2:Q332),2)
A18: Crypto Trading Bots | B18: =COUNTIF(Products!D2:D332,A18) | C18: =ROUND(AVERAGEIF(Products!D2:D332,A18,Products!E2:E332),2) | D18: =IFERROR(ROUND(AVERAGEIF(Products!D2:D332,A18,Products!S2:S332),2),"N/A") | E18: =COUNTIFS(Products!D2:D332,A18,Products!J2:J332,TRUE) | F18: =ROUND(E18/B18*100,1) | G18: =ROUND(AVERAGEIF(Products!D2:D332,A18,Products!Q2:Q332),2)
A19: Crypto Wallets | B19: =COUNTIF(Products!D2:D332,A19) | C19: =ROUND(AVERAGEIF(Products!D2:D332,A19,Products!E2:E332),2) | D19: =IFERROR(ROUND(AVERAGEIF(Products!D2:D332,A19,Products!S2:S332),2),"N/A") | E19: =COUNTIFS(Products!D2:D332,A19,Products!J2:J332,TRUE) | F19: =ROUND(E19/B19*100,1) | G19: =ROUND(AVERAGEIF(Products!D2:D332,A19,Products!Q2:Q332),2)
A20: DEX | B20: =COUNTIF(Products!D2:D332,A20) | C20: =ROUND(AVERAGEIF(Products!D2:D332,A20,Products!E2:E332),2) | D20: =IFERROR(ROUND(AVERAGEIF(Products!D2:D332,A20,Products!S2:S332),2),"N/A") | E20: =COUNTIFS(Products!D2:D332,A20,Products!J2:J332,TRUE) | F20: =ROUND(E20/B20*100,1) | G20: =ROUND(AVERAGEIF(Products!D2:D332,A20,Products!Q2:Q332),2)
A21: DeFi Tools | B21: =COUNTIF(Products!D2:D332,A21) | C21: =ROUND(AVERAGEIF(Products!D2:D332,A21,Products!E2:E332),2) | D21: =IFERROR(ROUND(AVERAGEIF(Products!D2:D332,A21,Products!S2:S332),2),"N/A") | E21: =COUNTIFS(Products!D2:D332,A21,Products!J2:J332,TRUE) | F21: =ROUND(E21/B21*100,1) | G21: =ROUND(AVERAGEIF(Products!D2:D332,A21,Products!Q2:Q332),2)
A22: Design Tools | B22: =COUNTIF(Products!D2:D332,A22) | C22: =ROUND(AVERAGEIF(Products!D2:D332,A22,Products!E2:E332),2) | D22: =IFERROR(ROUND(AVERAGEIF(Products!D2:D332,A22,Products!S2:S332),2),"N/A") | E22: =COUNTIFS(Products!D2:D332,A22,Products!J2:J332,TRUE) | F22: =ROUND(E22/B22*100,1) | G22: =ROUND(AVERAGEIF(Products!D2:D332,A22,Products!Q2:Q332),2)
A23: Email Marketing | B23: =COUNTIF(Products!D2:D332,A23) | C23: =ROUND(AVERAGEIF(Products!D2:D332,A23,Products!E2:E332),2) | D23: =IFERROR(ROUND(AVERAGEIF(Products!D2:D332,A23,Products!S2:S332),2),"N/A") | E23: =COUNTIFS(Products!D2:D332,A23,Products!J2:J332,TRUE) | F23: =ROUND(E23/B23*100,1) | G23: =ROUND(AVERAGEIF(Products!D2:D332,A23,Products!Q2:Q332),2)
A24: Large Language Models | B24: =COUNTIF(Products!D2:D332,A24) | C24: =ROUND(AVERAGEIF(Products!D2:D332,A24,Products!E2:E332),2) | D24: =IFERROR(ROUND(AVERAGEIF(Products!D2:D332,A24,Products!S2:S332),2),"N/A") | E24: =COUNTIFS(Products!D2:D332,A24,Products!J2:J332,TRUE) | F24: =ROUND(E24/B24*100,1) | G24: =ROUND(AVERAGEIF(Products!D2:D332,A24,Products!Q2:Q332),2)
A25: Password Managers | B25: =COUNTIF(Products!D2:D332,A25) | C25: =ROUND(AVERAGEIF(Products!D2:D332,A25,Products!E2:E332),2) | D25: =IFERROR(ROUND(AVERAGEIF(Products!D2:D332,A25,Products!S2:S332),2),"N/A") | E25: =COUNTIFS(Products!D2:D332,A25,Products!J2:J332,TRUE) | F25: =ROUND(E25/B25*100,1) | G25: =ROUND(AVERAGEIF(Products!D2:D332,A25,Products!Q2:Q332),2)
A26: Project Management | B26: =COUNTIF(Products!D2:D332,A26) | C26: =ROUND(AVERAGEIF(Products!D2:D332,A26,Products!E2:E332),2) | D26: =IFERROR(ROUND(AVERAGEIF(Products!D2:D332,A26,Products!S2:S332),2),"N/A") | E26: =COUNTIFS(Products!D2:D332,A26,Products!J2:J332,TRUE) | F26: =ROUND(E26/B26*100,1) | G26: =ROUND(AVERAGEIF(Products!D2:D332,A26,Products!Q2:Q332),2)
A27: VPN | B27: =COUNTIF(Products!D2:D332,A27) | C27: =ROUND(AVERAGEIF(Products!D2:D332,A27,Products!E2:E332),2) | D27: =IFERROR(ROUND(AVERAGEIF(Products!D2:D332,A27,Products!S2:S332),2),"N/A") | E27: =COUNTIFS(Products!D2:D332,A27,Products!J2:J332,TRUE) | F27: =ROUND(E27/B27*100,1) | G27: =ROUND(AVERAGEIF(Products!D2:D332,A27,Products!Q2:Q332),2)
A28: Video Conferencing | B28: =COUNTIF(Products!D2:D332,A28) | C28: =ROUND(AVERAGEIF(Products!D2:D332,A28,Products!E2:E332),2) | D28: =IFERROR(ROUND(AVERAGEIF(Products!D2:D332,A28,Products!S2:S332),2),"N/A") | E28: =COUNTIFS(Products!D2:D332,A28,Products!J2:J332,TRUE) | F28: =ROUND(E28/B28*100,1) | G28: =ROUND(AVERAGEIF(Products!D2:D332,A28,Products!Q2:Q332),2)
A29: Website Builders | B29: =COUNTIF(Products!D2:D332,A29) | C29: =ROUND(AVERAGEIF(Products!D2:D332,A29,Products!E2:E332),2) | D29: =IFERROR(ROUND(AVERAGEIF(Products!D2:D332,A29,Products!S2:S332),2),"N/A") | E29: =COUNTIFS(Products!D2:D332,A29,Products!J2:J332,TRUE) | F29: =ROUND(E29/B29*100,1) | G29: =ROUND(AVERAGEIF(Products!D2:D332,A29,Products!Q2:Q332),2)
A31: Note: 'DEX' avg_entry_price shows N/A — its listed prices are swap-fee %, not USD/month subscriptions.

Sheet Billing Models
A1: billing_model | B1: plan_count | C1: pct_of_plans
A2: flat | B2: =COUNTIF('Pricing Plans'!F2:F1014,A2) | C2: =ROUND(B2/SUM($B$2:$B$5)*100,1)
A3: per-seat | B3: =COUNTIF('Pricing Plans'!F2:F1014,A3) | C3: =ROUND(B3/SUM($B$2:$B$5)*100,1)
A4: usage-based | B4: =COUNTIF('Pricing Plans'!F2:F1014,A4) | C4: =ROUND(B4/SUM($B$2:$B$5)*100,1)
A5: per-project | B5: =COUNTIF('Pricing Plans'!F2:F1014,A5) | C5: =ROUND(B5/SUM($B$2:$B$5)*100,1)
